Workbook

Sheet ReadMe
A1: Trailhead Burger Co. — Financial & Accounting Analysis Workbook
A2: A fictional 5-restaurant chain, built to practice the skills in the Whataburger Accounting Data Analyst posting.
A4: How this workbook is organized:
A5: Chart_of_Accounts, Restaurants, Vendors -> reference/lookup tables
A6: Transactions -> the journal entry detail (every row is one debit OR credit line; each Transaction_ID has a matching debit and credit line, so debits always = credits)
A7: General_Ledger -> account balances rolled up from Transactions (SUMIF)
A8: Trial_Balance -> proves total debits = total credits across the whole ledger
A9: Income_Statement -> monthly Revenue -> Gross Profit -> Operating Income by company
A10: Budget -> your editable budget assumptions (blue cells)
A11: Variance_Analysis -> Actual vs. Budget, $ and % variance, favorable/unfavorable flag
A12: Restaurant_Drilldown -> March food-cost variance broken out by restaurant (there's a planted anomaly here on purpose - see if you can find and explain it)
A14: Color legend:
... A31: 4. Try swapping the Budget assumptions and watch Variance_Analysis and Income_Statement react.

Sheet Chart_of_Accounts
A1: Account_ID | B1: Account_Name | C1: Account_Type | D1: Normal_Balance
A2: 1000 | B2: Cash | C2: Asset | D2: Debit
A3: 1010 | B3: Accounts Receivable | C3: Asset | D3: Debit
A4: 1020 | B4: Inventory | C4: Asset | D4: Debit
A5: 1030 | B5: Equipment | C5: Asset | D5: Debit
A6: 2000 | B6: Accounts Payable | C6: Liability | D6: Credit
A7: 2010 | B7: Loan Payable | C7: Liability | D7: Credit
A8: 3000 | B8: Owner's Equity | C8: Equity | D8: Credit
A9: 4000 | B9: Restaurant Sales | C9: Revenue | D9: Credit
A10: 4010 | B10: Delivery Sales | C10: Revenue | D10: Credit
A11: 5000 | B11: Food Cost | C11: Expense | D11: Debit
A12: 5010 | B12: Labor | C12: Expense | D12: Debit
... A18: 5070 | B18: Franchise Fees | C18: Expense | D18: Debit

Sheet Restaurants
A1: Restaurant_ID | B1: Restaurant_Name
A2: 101 | B2: Trailhead Burger Co. #101 - San Antonio, TX
A3: 102 | B3: Trailhead Burger Co. #102 - Austin, TX
A4: 103 | B4: Trailhead Burger Co. #103 - Corpus Christi, TX
A5: 104 | B5: Trailhead Burger Co. #104 - Laredo, TX
A6: 105 | B6: Trailhead Burger Co. #105 - Houston, TX

Sheet Vendors
A1: Vendor_ID | B1: Vendor_Name
A2: V01 | B2: Gulf Coast Meat Supply
A3: V02 | B3: Fresh Produce Partners
A4: V03 | B4: Lone Star Beverage Distributing
A5: V04 | B5: Southwest Packaging Co.
A6: V05 | B6: QuickDash Delivery Platform
A7: V07 | B7: CityWide Utilities
A8: V08 | B8: Prime Property Management
A9: V09 | B9: BrightSign Marketing Agency
A10: V10 | B10: Trailhead Burger Co. - Corporate

Sheet Pivot Revenue
A1: Account_Name | B1: (Multiple Items)
A3: Sum of Credit | B3: Column Labels
B4: Jan | C4: Feb | D4: Mar | E4: Grand Total
A6: Row Labels
A7: Trailhead Burger Co. #101 - San Antonio, TX | B7: 122000 | C7: 124440 | D7: 126880 | E7: 373320
A8: Trailhead Burger Co. #102 - Austin, TX | B8: 115900 | C8: 118218 | D8: 120536 | E8: 354654
A9: Trailhead Burger Co. #103 - Corpus Christi, TX | B9: 97600 | C9: 99552 | D9: 101504 | E9: 298656
A10: Trailhead Burger Co. #104 - Laredo, TX | B10: 103700 | C10: 105774 | D10: 107848 | E10: 317322
A11: Trailhead Burger Co. #105 - Houston, TX | B11: 134200 | C11: 136884 | D11: 139568 | E11: 410652
A12: Grand Total | B12: 573400 | C12: 584868 | D12: 596336 | E12: 1754604

Sheet Pivot Food Cost
A1: Account_Name | B1: Food Cost
A3: Sum of Debit | B3: Column Labels
B4: Jan | C4: Feb | D4: Mar | E4: Grand Total
A6: Row Labels
A7: Trailhead Burger Co. #101 - San Antonio, TX | B7: 36600 | C7: 37332 | D7: 38064 | E7: 111996
A8: Trailhead Burger Co. #102 - Austin, TX | B8: 34770 | C8: 35465.4 | D8: 36160.8 | E8: 106396.2
A9: Trailhead Burger Co. #103 - Corpus Christi, TX | B9: 29280 | C9: 29865.6 | D9: 30451.2 | E9: 89596.8
A10: Trailhead Burger Co. #104 - Laredo, TX | B10: 31110 | C10: 31732.2 | D10: 45296.16 | E10: 108138.36
A11: Trailhead Burger Co. #105 - Houston, TX | B11: 40260 | C11: 41065.2 | D11: 41870.4 | E11: 123195.6
A12: Grand Total | B12: 172020 | C12: 175460.4 | D12: 191842.56 | E12: 539322.96

Sheet Pivot Food Cost Pct
A1: Account_Name | B1: (Multiple Items)
B3: Column Labels
B4: Jan | E4: Feb | H4: Mar | K4: Total Sum of Credit | L4: Total Sum of Debit | M4: Total Sum of Food_Cost_Pct
A7: Row Labels | B7: Sum of Credit | C7: Sum of Debit | D7: Sum of Food_Cost_Pct | E7: Sum of Credit | F7: Sum of Debit | G7: Sum of Food_Cost_Pct | H7: Sum of Credit | I7: Sum of Debit | J7: Sum of Food_Cost_Pct
A8: Trailhead Burger Co. #101 - San Antonio, TX | B8: 122000 | C8: 36600 | D8: 0.3 | E8: 124440 | F8: 37332 | G8: 0.3 | H8: 126880 | I8: 38064 | J8: 0.3 | K8: 373320 | L8: 111996 | M8: 0.3
A9: Trailhead Burger Co. #102 - Austin, TX | B9: 115900 | C9: 34770 | D9: 0.3 | E9: 118218 | F9: 35465.4 | G9: 0.3 | H9: 120536 | I9: 36160.8 | J9: 0.3 | K9: 354654 | L9: 106396.2 | M9: 0.3
A10: Trailhead Burger Co. #103 - Corpus Christi, TX | B10: 97600 | C10: 29280 | D10: 0.3 | E10: 99552 | F10: 29865.6 | G10: 0.3 | H10: 101504 | I10: 30451.2 | J10: 0.3 | K10: 298656 | L10: 89596.8 | M10: 0.3
A11: Trailhead Burger Co. #104 - Laredo, TX | B11: 103700 | C11: 31110 | D11: 0.3 | E11: 105774 | F11: 31732.2 | G11: 0.3 | H11: 107848 | I11: 45296.16 | J11: 0.42 | K11: 317322 | L11: 108138.36 | M11: 0.34078431
A12: Trailhead Burger Co. #105 - Houston, TX | B12: 134200 | C12: 40260 | D12: 0.3 | E12: 136884 | F12: 41065.2 | G12: 0.3 | H12: 139568 | I12: 41870.4 | J12: 0.3 | K12: 410652 | L12: 123195.6 | M12: 0.3
A13: Grand Total | B13: 573400 | C13: 172020 | D13: 0.3 | E13: 584868 | F13: 175460.4 | G13: 0.3 | H13: 596336 | I13: 191842.56 | J13: 0.32170213 | K13: 1754604 | L13: 539322.96 | M13: 0.30737589

Sheet Transactions
A1: Line_ID | B1: Transaction_ID | C1: Date | D1: Restaurant_ID | E1: Restaurant_Name | F1: Account_ID | G1: Account_Name | H1: Account_Type | I1: Debit | J1: Credit | K1: Description | L1: Payment_Method | M1: Channel | N1: Vendor_ID | O1: Vendor_Name | P1: Department
A2: 1 | B2: T0001 | C2: 46024 | D2: 101 | E2: =IFERROR(INDEX(Restaurants!$B$2:$B$6,MATCH(D2,Restaurants!$A$2:$A$6,0)),"") -> Trailhead Burger Co. #101 - San Antonio, TX | F2: 1000 | G2: =IFERROR(INDEX(Chart_of_Accounts!$B$2:$B$18,MATCH(F2,Chart_of_Accounts!$A$2:$A$18,0)),"") -> Cash | H2: =IFERROR(INDEX(Chart_of_Accounts!$C$2:$C$18,MATCH(F2,Chart_of_Accounts!$A$2:$A$18,0)),"") -> Asset | I2: 60000 | K2: Owner capital contribution | L2: N/A | M2: Corporate | P2: Finance
A3: 1 | B3: T0001 | C3: 46024 | D3: 101 | E3: =IFERROR(INDEX(Restaurants!$B$2:$B$6,MATCH(D3,Restaurants!$A$2:$A$6,0)),"") -> Trailhead Burger Co. #101 - San Antonio, TX | F3: 3000 | G3: =IFERROR(INDEX(Chart_of_Accounts!$B$2:$B$18,MATCH(F3,Chart_of_Accounts!$A$2:$A$18,0)),"") -> Owner's Equity | H3: =IFERROR(INDEX(Chart_of_Accounts!$C$2:$C$18,MATCH(F3,Chart_of_Accounts!$A$2:$A$18,0)),"") -> Equity | J3: 60000 | K3: Owner capital contribution | L3: N/A | M3: Corporate | P3: Finance
A4: 2 | B4: T0002 | C4: 46024 | D4: 101 | E4: =IFERROR(INDEX(Restaurants!$B$2:$B$6,MATCH(D4,Restaurants!$A$2:$A$6,0)),"") -> Trailhead Burger Co. #101 - San Antonio, TX | F4: 1000 | G4: =IFERROR(INDEX(Chart_of_Accounts!$B$2:$B$18,MATCH(F4,Chart_of_Accounts!$A$2:$A$18,0)),"") -> Cash | H4: =IFERROR(INDEX(Chart_of_Accounts!$C$2:$C$18,MATCH(F4,Chart_of_Accounts!$A$2:$A$18,0)),"") -> Asset | I4: 40000 | K4: Proceeds from equipment loan | L4: N/A | M4: Corporate | P4: Finance
A5: 2 | B5: T0002 | C5: 46024 | D5: 101 | E5: =IFERROR(INDEX(Restaurants!$B$2:$B$6,MATCH(D5,Restaurants!$A$2:$A$6,0)),"") -> Trailhead Burger Co. #101 - San Antonio, TX | F5: 2010 | G5: =IFERROR(INDEX(Chart_of_Accounts!$B$2:$B$18,MATCH(F5,Chart_of_Accounts!$A$2:$A$18,0)),"") -> Loan Payable | H5: =IFERROR(INDEX(Chart_of_Accounts!$C$2:$C$18,MATCH(F5,Chart_of_Accounts!$A$2:$A$18,0)),"") -> Liability | J5: 40000 | K5: Proceeds from equipment loan | L5: N/A | M5: Corporate | P5: Finance
A6: 3 | B6: T0003 | C6: 46024 | D6: 101 | E6: =IFERROR(INDEX(Restaurants!$B$2:$B$6,MATCH(D6,Restaurants!$A$2:$A$6,0)),"") -> Trailhead Burger Co. #101 - San Antonio, TX | F6: 1030 | G6: =IFERROR(INDEX(Chart_of_Accounts!$B$2:$B$18,MATCH(F6,Chart_of_Accounts!$A$2:$A$18,0)),"") -> Equipment | H6: =IFERROR(INDEX(Chart_of_Accounts!$C$2:$C$18,MATCH(F6,Chart_of_Accounts!$A$2:$A$18,0)),"") -> Asset | I6: 95000 | K6: Purchase of kitchen equipment | L6: N/A | M6: Corporate | N6: V10 | O6: =IFERROR(INDEX(Vendors!$B$2:$B$10,MATCH(N6,Vendors!$A$2:$A$10,0)),"") -> Trailhead Burger Co. - Corporate | P6: Operations
A7: 3 | B7: T0003 | C7: 46024 | D7: 101 | E7: =IFERROR(INDEX(Restaurants!$B$2:$B$6,MATCH(D7,Restaurants!$A$2:$A$6,0)),"") -> Trailhead Burger Co. #101 - San Antonio, TX | F7: 1000 | G7: =IFERROR(INDEX(Chart_of_Accounts!$B$2:$B$18,MATCH(F7,Chart_of_Accounts!$A$2:$A$18,0)),"") -> Cash | H7: =IFERROR(INDEX(Chart_of_Accounts!$C$2:$C$18,MATCH(F7,Chart_of_Accounts!$A$2:$A$18,0)),"") -> Asset | J7: 95000 | K7: Purchase of kitchen equipment | L7: N/A | M7: Corporate | N7: V10 | O7: =IFERROR(INDEX(Vendors!$B$2:$B$10,MATCH(N7,Vendors!$A$2:$A$10,0)),"") -> Trailhead Burger Co. - Corporate | P7: Operations
A8: 4 | B8: T0004 | C8: 46024 | D8: 102 | E8: =IFERROR(INDEX(Restaurants!$B$2:$B$6,MATCH(D8,Restaurants!$A$2:$A$6,0)),"") -> Trailhead Burger Co. #102 - Austin, TX | F8: 1000 | G8: =IFERROR(INDEX(Chart_of_Accounts!$B$2:$B$18,MATCH(F8,Chart_of_Accounts!$A$2:$A$18,0)),"") -> Cash | H8: =IFERROR(INDEX(Chart_of_Accounts!$C$2:$C$18,MATCH(F8,Chart_of_Accounts!$A$2:$A$18,0)),"") -> Asset | I8: 60000 | K8: Owner capital contribution | L8: N/A | M8: Corporate | P8: Finance
A9: 4 | B9: T0004 | C9: 46024 | D9: 102 | E9: =IFERROR(INDEX(Restaurants!$B$2:$B$6,MATCH(D9,Restaurants!$A$2:$A$6,0)),"") -> Trailhead Burger Co. #102 - Austin, TX | F9: 3000 | G9: =IFERROR(INDEX(Chart_of_Accounts!$B$2:$B$18,MATCH(F9,Chart_of_Accounts!$A$2:$A$18,0)),"") -> Owner's Equity | H9: =IFERROR(INDEX(Chart_of_Accounts!$C$2:$C$18,MATCH(F9,Chart_of_Accounts!$A$2:$A$18,0)),"") -> Equity | J9: 60000 | K9: Owner capital contribution | L9: N/A | M9: Corporate | P9: Finance
A10: 5 | B10: T0005 | C10: 46024 | D10: 102 | E10: =IFERROR(INDEX(Restaurants!$B$2:$B$6,MATCH(D10,Restaurants!$A$2:$A$6,0)),"") -> Trailhead Burger Co. #102 - Austin, TX | F10: 1000 | G10: =IFERROR(INDEX(Chart_of_Accounts!$B$2:$B$18,MATCH(F10,Chart_of_Accounts!$A$2:$A$18,0)),"") -> Cash | H10: =IFERROR(INDEX(Chart_of_Accounts!$C$2:$C$18,MATCH(F10,Chart_of_Accounts!$A$2:$A$18,0)),"") -> Asset | I10: 40000 | K10: Proceeds from equipment loan | L10: N/A | M10: Corporate | P10: Finance
A11: 5 | B11: T0005 | C11: 46024 | D11: 102 | E11: =IFERROR(INDEX(Restaurants!$B$2:$B$6,MATCH(D11,Restaurants!$A$2:$A$6,0)),"") -> Trailhead Burger Co. #102 - Austin, TX | F11: 2010 | G11: =IFERROR(INDEX(Chart_of_Accounts!$B$2:$B$18,MATCH(F11,Chart_of_Accounts!$A$2:$A$18,0)),"") -> Loan Payable | H11: =IFERROR(INDEX(Chart_of_Accounts!$C$2:$C$18,MATCH(F11,Chart_of_Accounts!$A$2:$A$18,0)),"") -> Liability | J11: 40000 | K11: Proceeds from equipment loan | L11: N/A | M11: Corporate | P11: Finance
A12: 6 | B12: T0006 | C12: 46024 | D12: 102 | E12: =IFERROR(INDEX(Restaurants!$B$2:$B$6,MATCH(D12,Restaurants!$A$2:$A$6,0)),"") -> Trailhead Burger Co. #102 - Austin, TX | F12: 1030 | G12: =IFERROR(INDEX(Chart_of_Accounts!$B$2:$B$18,MATCH(F12,Chart_of_Accounts!$A$2:$A$18,0)),"") -> Equipment | H12: =IFERROR(INDEX(Chart_of_Accounts!$C$2:$C$18,MATCH(F12,Chart_of_Accounts!$A$2:$A$18,0)),"") -> Asset | I12: 95000 | K12: Purchase of kitchen equipment | L12: N/A | M12: Corporate | N12: V10 | O12: =IFERROR(INDEX(Vendors!$B$2:$B$10,MATCH(N12,Vendors!$A$2:$A$10,0)),"") -> Trailhead Burger Co. - Corporate | P12: Operations
A13: 6 | B13: T0006 | C13: 46024 | D13: 102 | E13: =IFERROR(INDEX(Restaurants!$B$2:$B$6,MATCH(D13,Restaurants!$A$2:$A$6,0)),"") -> Trailhead Burger Co. #102 - Austin, TX | F13: 1000 | G13: =IFERROR(INDEX(Chart_of_Accounts!$B$2:$B$18,MATCH(F13,Chart_of_Accounts!$A$2:$A$18,0)),"") -> Cash | H13: =IFERROR(INDEX(Chart_of_Accounts!$C$2:$C$18,MATCH(F13,Chart_of_Accounts!$A$2:$A$18,0)),"") -> Asset | J13: 95000 | K13: Purchase of kitchen equipment | L13: N/A | M13: Corporate | N13: V10 | O13: =IFERROR(INDEX(Vendors!$B$2:$B$10,MATCH(N13,Vendors!$A$2:$A$10,0)),"") -> Trailhead Burger Co. - Corporate | P13: Operations
A14: 7 | B14: T0007 | C14: 46024 | D14: 103 | E14: =IFERROR(INDEX(Restaurants!$B$2:$B$6,MATCH(D14,Restaurants!$A$2:$A$6,0)),"") -> Trailhead Burger Co. #103 - Corpus Christi, TX | F14: 1000 | G14: =IFERROR(INDEX(Chart_of_Accounts!$B$2:$B$18,MATCH(F14,Chart_of_Accounts!$A$2:$A$18,0)),"") -> Cash | H14: =IFERROR(INDEX(Chart_of_Accounts!$C$2:$C$18,MATCH(F14,Chart_of_Accounts!$A$2:$A$18,0)),"") -> Asset | I14: 60000 | K14: Owner capital contribution | L14: N/A | M14: Corporate | P14: Finance
A15: 7 | B15: T0007 | C15: 46024 | D15: 103 | E15: =IFERROR(INDEX(Restaurants!$B$2:$B$6,MATCH(D15,Restaurants!$A$2:$A$6,0)),"") -> Trailhead Burger Co. #103 - Corpus Christi, TX | F15: 3000 | G15: =IFERROR(INDEX(Chart_of_Accounts!$B$2:$B$18,MATCH(F15,Chart_of_Accounts!$A$2:$A$18,0)),"") -> Owner's Equity | H15: =IFERROR(INDEX(Chart_of_Accounts!$C$2:$C$18,MATCH(F15,Chart_of_Accounts!$A$2:$A$18,0)),"") -> Equity | J15: 60000 | K15: Owner capital contribution | L15: N/A | M15: Corporate | P15: Finance
A16: 8 | B16: T0008 | C16: 46024 | D16: 103 | E16: =IFERROR(INDEX(Restaurants!$B$2:$B$6,MATCH(D16,Restaurants!$A$2:$A$6,0)),"") -> Trailhead Burger Co. #103 - Corpus Christi, TX | F16: 1000 | G16: =IFERROR(INDEX(Chart_of_Accounts!$B$2:$B$18,MATCH(F16,Chart_of_Accounts!$A$2:$A$18,0)),"") -> Cash | H16: =IFERROR(INDEX(Chart_of_Accounts!$C$2:$C$18,MATCH(F16,Chart_of_Accounts!$A$2:$A$18,0)),"") -> Asset | I16: 40000 | K16: Proceeds from equipment loan | L16: N/A | M16: Corporate | P16: Finance
A17: 8 | B17: T0008 | C17: 46024 | D17: 103 | E17: =IFERROR(INDEX(Restaurants!$B$2:$B$6,MATCH(D17,Restaurants!$A$2:$A$6,0)),"") -> Trailhead Burger Co. #103 - Corpus Christi, TX | F17: 2010 | G17: =IFERROR(INDEX(Chart_of_Accounts!$B$2:$B$18,MATCH(F17,Chart_of_Accounts!$A$2:$A$18,0)),"") -> Loan Payable | H17: =IFERROR(INDEX(Chart_of_Accounts!$C$2:$C$18,MATCH(F17,Chart_of_Accounts!$A$2:$A$18,0)),"") -> Liability | J17: 40000 | K17: Proceeds from equipment loan | L17: N/A | M17: Corporate | P17: Finance
A18: 9 | B18: T0009 | C18: 46024 | D18: 103 | E18: =IFERROR(INDEX(Restaurants!$B$2:$B$6,MATCH(D18,Restaurants!$A$2:$A$6,0)),"") -> Trailhead Burger Co. #103 - Corpus Christi, TX | F18: 1030 | G18: =IFERROR(INDEX(Chart_of_Accounts!$B$2:$B$18,MATCH(F18,Chart_of_Accounts!$A$2:$A$18,0)),"") -> Equipment | H18: =IFERROR(INDEX(Chart_of_Accounts!$C$2:$C$18,MATCH(F18,Chart_of_Accounts!$A$2:$A$18,0)),"") -> Asset | I18: 95000 | K18: Purchase of kitchen equipment | L18: N/A | M18: Corporate | N18: V10 | O18: =IFERROR(INDEX(Vendors!$B$2:$B$10,MATCH(N18,Vendors!$A$2:$A$10,0)),"") -> Trailhead Burger Co. - Corporate | P18: Operations
A19: 9 | B19: T0009 | C19: 46024 | D19: 103 | E19: =IFERROR(INDEX(Restaurants!$B$2:$B$6,MATCH(D19,Restaurants!$A$2:$A$6,0)),"") -> Trailhead Burger Co. #103 - Corpus Christi, TX | F19: 1000 | G19: =IFERROR(INDEX(Chart_of_Accounts!$B$2:$B$18,MATCH(F19,Chart_of_Accounts!$A$2:$A$18,0)),"") -> Cash | H19: =IFERROR(INDEX(Chart_of_Accounts!$C$2:$C$18,MATCH(F19,Chart_of_Accounts!$A$2:$A$18,0)),"") -> Asset | J19: 95000 | K19: Purchase of kitchen equipment | L19: N/A | M19: Corporate | N19: V10 | O19: =IFERROR(INDEX(Vendors!$B$2:$B$10,MATCH(N19,Vendors!$A$2:$A$10,0)),"") -> Trailhead Burger Co. - Corporate | P19: Operations
A20: 10 | B20: T0010 | C20: 46024 | D20: 104 | E20: =IFERROR(INDEX(Restaurants!$B$2:$B$6,MATCH(D20,Restaurants!$A$2:$A$6,0)),"") -> Trailhead Burger Co. #104 - Laredo, TX | F20: 1000 | G20: =IFERROR(INDEX(Chart_of_Accounts!$B$2:$B$18,MATCH(F20,Chart_of_Accounts!$A$2:$A$18,0)),"") -> Cash | H20: =IFERROR(INDEX(Chart_of_Accounts!$C$2:$C$18,MATCH(F20,Chart_of_Accounts!$A$2:$A$18,0)),"") -> Asset | I20: 60000 | K20: Owner capital contribution | L20: N/A | M20: Corporate | P20: Finance
A21: 10 | B21: T0010 | C21: 46024 | D21: 104 | E21: =IFERROR(INDEX(Restaurants!$B$2:$B$6,MATCH(D21,Restaurants!$A$2:$A$6,0)),"") -> Trailhead Burger Co. #104 - Laredo, TX | F21: 3000 | G21: =IFERROR(INDEX(Chart_of_Accounts!$B$2:$B$18,MATCH(F21,Chart_of_Accounts!$A$2:$A$18,0)),"") -> Owner's Equity | H21: =IFERROR(INDEX(Chart_of_Accounts!$C$2:$C$18,MATCH(F21,Chart_of_Accounts!$A$2:$A$18,0)),"") -> Equity | J21: 60000 | K21: Owner capital contribution | L21: N/A | M21: Corporate | P21: Finance
A22: 11 | B22: T0011 | C22: 46024 | D22: 104 | E22: =IFERROR(INDEX(Restaurants!$B$2:$B$6,MATCH(D22,Restaurants!$A$2:$A$6,0)),"") -> Trailhead Burger Co. #104 - Laredo, TX | F22: 1000 | G22: =IFERROR(INDEX(Chart_of_Accounts!$B$2:$B$18,MATCH(F22,Chart_of_Accounts!$A$2:$A$18,0)),"") -> Cash | H22: =IFERROR(INDEX(Chart_of_Accounts!$C$2:$C$18,MATCH(F22,Chart_of_Accounts!$A$2:$A$18,0)),"") -> Asset | I22: 40000 | K22: Proceeds from equipment loan | L22: N/A | M22: Corporate | P22: Finance
A23: 11 | B23: T0011 | C23: 46024 | D23: 104 | E23: =IFERROR(INDEX(Restaurants!$B$2:$B$6,MATCH(D23,Restaurants!$A$2:$A$6,0)),"") -> Trailhead Burger Co. #104 - Laredo, TX | F23: 2010 | G23: =IFERROR(INDEX(Chart_of_Accounts!$B$2:$B$18,MATCH(F23,Chart_of_Accounts!$A$2:$A$18,0)),"") -> Loan Payable | H23: =IFERROR(INDEX(Chart_of_Accounts!$C$2:$C$18,MATCH(F23,Chart_of_Accounts!$A$2:$A$18,0)),"") -> Liability | J23: 40000 | K23: Proceeds from equipment loan | L23: N/A | M23: Corporate | P23: Finance
A24: 12 | B24: T0012 | C24: 46024 | D24: 104 | E24: =IFERROR(INDEX(Restaurants!$B$2:$B$6,MATCH(D24,Restaurants!$A$2:$A$6,0)),"") -> Trailhead Burger Co. #104 - Laredo, TX | F24: 1030 | G24: =IFERROR(INDEX(Chart_of_Accounts!$B$2:$B$18,MATCH(F24,Chart_of_Accounts!$A$2:$A$18,0)),"") -> Equipment | H24: =IFERROR(INDEX(Chart_of_Accounts!$C$2:$C$18,MATCH(F24,Chart_of_Accounts!$A$2:$A$18,0)),"") -> Asset | I24: 95000 | K24: Purchase of kitchen equipment | L24: N/A | M24: Corporate | N24: V10 | O24: =IFERROR(INDEX(Vendors!$B$2:$B$10,MATCH(N24,Vendors!$A$2:$A$10,0)),"") -> Trailhead Burger Co. - Corporate | P24: Operations
A25: 12 | B25: T0012 | C25: 46024 | D25: 104 | E25: =IFERROR(INDEX(Restaurants!$B$2:$B$6,MATCH(D25,Restaurants!$A$2:$A$6,0)),"") -> Trailhead Burger Co. #104 - Laredo, TX | F25: 1000 | G25: =IFERROR(INDEX(Chart_of_Accounts!$B$2:$B$18,MATCH(F25,Chart_of_Accounts!$A$2:$A$18,0)),"") -> Cash | H25: =IFERROR(INDEX(Chart_of_Accounts!$C$2:$C$18,MATCH(F25,Chart_of_Accounts!$A$2:$A$18,0)),"") -> Asset | J25: 95000 | K25: Purchase of kitchen equipment | L25: N/A | M25: Corporate | N25: V10 | O25: =IFERROR(INDEX(Vendors!$B$2:$B$10,MATCH(N25,Vendors!$A$2:$A$10,0)),"") -> Trailhead Burger Co. - Corporate | P25: Operations
A26: 13 | B26: T0013 | C26: 46024 | D26: 105 | E26: =IFERROR(INDEX(Restaurants!$B$2:$B$6,MATCH(D26,Restaurants!$A$2:$A$6,0)),"") -> Trailhead Burger Co. #105 - Houston, TX | F26: 1000 | G26: =IFERROR(INDEX(Chart_of_Accounts!$B$2:$B$18,MATCH(F26,Chart_of_Accounts!$A$2:$A$18,0)),"") -> Cash | H26: =IFERROR(INDEX(Chart_of_Accounts!$C$2:$C$18,MATCH(F26,Chart_of_Accounts!$A$2:$A$18,0)),"") -> Asset | I26: 60000 | K26: Owner capital contribution | L26: N/A | M26: Corporate | P26: Finance
A27: 13 | B27: T0013 | C27: 46024 | D27: 105 | E27: =IFERROR(INDEX(Restaurants!$B$2:$B$6,MATCH(D27,Restaurants!$A$2:$A$6,0)),"") -> Trailhead Burger Co. #105 - Houston, TX | F27: 3000 | G27: =IFERROR(INDEX(Chart_of_Accounts!$B$2:$B$18,MATCH(F27,Chart_of_Accounts!$A$2:$A$18,0)),"") -> Owner's Equity | H27: =IFERROR(INDEX(Chart_of_Accounts!$C$2:$C$18,MATCH(F27,Chart_of_Accounts!$A$2:$A$18,0)),"") -> Equity | J27: 60000 | K27: Owner capital contribution | L27: N/A | M27: Corporate | P27: Finance
A28: 14 | B28: T0014 | C28: 46024 | D28: 105 | E28: =IFERROR(INDEX(Restaurants!$B$2:$B$6,MATCH(D28,Restaurants!$A$2:$A$6,0)),"") -> Trailhead Burger Co. #105 - Houston, TX | F28: 1000 | G28: =IFERROR(INDEX(Chart_of_Accounts!$B$2:$B$18,MATCH(F28,Chart_of_Accounts!$A$2:$A$18,0)),"") -> Cash | H28: =IFERROR(INDEX(Chart_of_Accounts!$C$2:$C$18,MATCH(F28,Chart_of_Accounts!$A$2:$A$18,0)),"") -> Asset | I28: 40000 | K28: Proceeds from equipment loan | L28: N/A | M28: Corporate | P28: Finance
A29: 14 | B29: T0014 | C29: 46024 | D29: 105 | E29: =IFERROR(INDEX(Restaurants!$B$2:$B$6,MATCH(D29,Restaurants!$A$2:$A$6,0)),"") -> Trailhead Burger Co. #105 - Houston, TX | F29: 2010 | G29: =IFERROR(INDEX(Chart_of_Accounts!$B$2:$B$18,MATCH(F29,Chart_of_Accounts!$A$2:$A$18,0)),"") -> Loan Payable | H29: =IFERROR(INDEX(Chart_of_Accounts!$C$2:$C$18,MATCH(F29,Chart_of_Accounts!$A$2:$A$18,0)),"") -> Liability | J29: 40000 | K29: Proceeds from equipment loan | L29: N/A | M29: Corporate | P29: Finance
A30: 15 | B30: T0015 | C30: 46024 | D30: 105 | E30: =IFERROR(INDEX(Restaurants!$B$2:$B$6,MATCH(D30,Restaurants!$A$2:$A$6,0)),"") -> Trailhead Burger Co. #105 - Houston, TX | F30: 1030 | G30: =IFERROR(INDEX(Chart_of_Accounts!$B$2:$B$18,MATCH(F30,Chart_of_Accounts!$A$2:$A$18,0)),"") -> Equipment | H30: =IFERROR(INDEX(Chart_of_Accounts!$C$2:$C$18,MATCH(F30,Chart_of_Accounts!$A$2:$A$18,0)),"") -> Asset | I30: 95000 | K30: Purchase of kitchen equipment | L30: N/A | M30: Corporate | N30: V10 | O30: =IFERROR(INDEX(Vendors!$B$2:$B$10,MATCH(N30,Vendors!$A$2:$A$10,0)),"") -> Trailhead Burger Co. - Corporate | P30: Operations
A31: 15 | B31: T0015 | C31: 46024 | D31: 105 | E31: =IFERROR(INDEX(Restaurants!$B$2:$B$6,MATCH(D31,Restaurants!$A$2:$A$6,0)),"") -> Trailhead Burger Co. #105 - Houston, TX | F31: 1000 | G31: =IFERROR(INDEX(Chart_of_Accounts!$B$2:$B$18,MATCH(F31,Chart_of_Accounts!$A$2:$A$18,0)),"") -> Cash | H31: =IFERROR(INDEX(Chart_of_Accounts!$C$2:$C$18,MATCH(F31,Chart_of_Accounts!$A$2:$A$18,0)),"") -> Asset | J31: 95000 | K31: Purchase of kitchen equipment | L31: N/A | M31: Corporate | N31: V10 | O31: =IFERROR(INDEX(Vendors!$B$2:$B$10,MATCH(N31,Vendors!$A$2:$A$10,0)),"") -> Trailhead Burger Co. - Corporate | P31: Operations
A32: 16 | B32: T0016 | C32: 46027 | D32: 101 | E32: =IFERROR(INDEX(Restaurants!$B$2:$B$6,MATCH(D32,Restaurants!$A$2:$A$6,0)),"") -> Trailhead Burger Co. #101 - San Antonio, TX | F32: 1000 | G32: =IFERROR(INDEX(Chart_of_Accounts!$B$2:$B$18,MATCH(F32,Chart_of_Accounts!$A$2:$A$18,0)),"") -> Cash | H32: =IFERROR(INDEX(Chart_of_Accounts!$C$2:$C$18,MATCH(F32,Chart_of_Accounts!$A$2:$A$18,0)),"") -> Asset | I32: 100000 | K32: Weekly dine-in & drive-thru sales | L32: Cash | M32: Dine-In | P32: Restaurant Ops
A33: 16 | B33: T0016 | C33: 46027 | D33: 101 | E33: =IFERROR(INDEX(Restaurants!$B$2:$B$6,MATCH(D33,Restaurants!$A$2:$A$6,0)),"") -> Trailhead Burger Co. #101 - San Antonio, TX | F33: 4000 | G33: =IFERROR(INDEX(Chart_of_Accounts!$B$2:$B$18,MATCH(F33,Chart_of_Accounts!$A$2:$A$18,0)),"") -> Restaurant Sales | H33: =IFERROR(INDEX(Chart_of_Accounts!$C$2:$C$18,MATCH(F33,Chart_of_Accounts!$A$2:$A$18,0)),"") -> Revenue | J33: 100000 | K33: Weekly dine-in & drive-thru sales | L33: Cash | M33: Dine-In | P33: Restaurant Ops
A34: 17 | B34: T0017 | C34: 46029 | D34: 101 | E34: =IFERROR(INDEX(Restaurants!$B$2:$B$6,MATCH(D34,Restaurants!$A$2:$A$6,0)),"") -> Trailhead Burger Co. #101 - San Antonio, TX | F34: 1010 | G34: =IFERROR(INDEX(Chart_of_Accounts!$B$2:$B$18,MATCH(F34,Chart_of_Accounts!$A$2:$A$18,0)),"") -> Accounts Receivable | H34: =IFERROR(INDEX(Chart_of_Accounts!$C$2:$C$18,MATCH(F34,Chart_of_Accounts!$A$2:$A$18,0)),"") -> Asset | I34: 22000 | K34: Delivery sales via QuickDash | L34: Delivery Platform Settlement | M34: Delivery | N34: V05 | O34: =IFERROR(INDEX(Vendors!$B$2:$B$10,MATCH(N34,Vendors!$A$2:$A$10,0)),"") -> QuickDash Delivery Platform | P34: Restaurant Ops
A35: 17 | B35: T0017 | C35: 46029 | D35: 101 | E35: =IFERROR(INDEX(Restaurants!$B$2:$B$6,MATCH(D35,Restaurants!$A$2:$A$6,0)),"") -> Trailhead Burger Co. #101 - San Antonio, TX | F35: 4010 | G35: =IFERROR(INDEX(Chart_of_Accounts!$B$2:$B$18,MATCH(F35,Chart_of_Accounts!$A$2:$A$18,0)),"") -> Delivery Sales | H35: =IFERROR(INDEX(Chart_of_Accounts!$C$2:$C$18,MATCH(F35,Chart_of_Accounts!$A$2:$A$18,0)),"") -> Revenue | J35: 22000 | K35: Delivery sales via QuickDash | L35: Delivery Platform Settlement | M35: Delivery | N35: V05 | O35: =IFERROR(INDEX(Vendors!$B$2:$B$10,MATCH(N35,Vendors!$A$2:$A$10,0)),"") -> QuickDash Delivery Platform | P35: Restaurant Ops
A36: 18 | B36: T0018 | C36: 46032 | D36: 101 | E36: =IFERROR(INDEX(Restaurants!$B$2:$B$6,MATCH(D36,Restaurants!$A$2:$A$6,0)),"") -> Trailhead Burger Co. #101 - San Antonio, TX | F36: 1000 | G36: =IFERROR(INDEX(Chart_of_Accounts!$B$2:$B$18,MATCH(F36,Chart_of_Accounts!$A$2:$A$18,0)),"") -> Cash | H36: =IFERROR(INDEX(Chart_of_Accounts!$C$2:$C$18,MATCH(F36,Chart_of_Accounts!$A$2:$A$18,0)),"") -> Asset | I36: 22000 | K36: Collection of delivery platform settlement | L36: Delivery Platform Settlement | M36: Delivery | N36: V05 | O36: =IFERROR(INDEX(Vendors!$B$2:$B$10,MATCH(N36,Vendors!$A$2:$A$10,0)),"") -> QuickDash Delivery Platform | P36: Restaurant Ops
A37: 18 | B37: T0018 | C37: 46032 | D37: 101 | E37: =IFERROR(INDEX(Restaurants!$B$2:$B$6,MATCH(D37,Restaurants!$A$2:$A$6,0)),"") -> Trailhead Burger Co. #101 - San Antonio, TX | F37: 1010 | G37: =IFERROR(INDEX(Chart_of_Accounts!$B$2:$B$18,MATCH(F37,Chart_of_Accounts!$A$2:$A$18,0)),"") -> Accounts Receivable | H37: =IFERROR(INDEX(Chart_of_Accounts!$C$2:$C$18,MATCH(F37,Chart_of_Accounts!$A$2:$A$18,0)),"") -> Asset | J37: 22000 | K37: Collection of delivery platform settlement | L37: Delivery Platform Settlement | M37: Delivery | N37: V05 | O37: =IFERROR(INDEX(Vendors!$B$2:$B$10,MATCH(N37,Vendors!$A$2:$A$10,0)),"") -> QuickDash Delivery Platform | P37: Restaurant Ops
A38: 19 | B38: T0019 | C38: 46032 | D38: 101 | E38: =IFERROR(INDEX(Restaurants!$B$2:$B$6,MATCH(D38,Restaurants!$A$2:$A$6,0)),"") -> Trailhead Burger Co. #101 - San Antonio, TX | F38: 5040 | G38: =IFERROR(INDEX(Chart_of_Accounts!$B$2:$B$18,MATCH(F38,Chart_of_Accounts!$A$2:$A$18,0)),"") -> Delivery Fees | H38: =IFERROR(INDEX(Chart_of_Accounts!$C$2:$C$18,MATCH(F38,Chart_of_Accounts!$A$2:$A$18,0)),"") -> Expense | I38: 3300 | K38: Delivery platform commission fee | L38: Cash | M38: Delivery | N38: V05 | O38: =IFERROR(INDEX(Vendors!$B$2:$B$10,MATCH(N38,Vendors!$A$2:$A$10,0)),"") -> QuickDash Delivery Platform | P38: Restaurant Ops
A39: 19 | B39: T0019 | C39: 46032 | D39: 101 | E39: =IFERROR(INDEX(Restaurants!$B$2:$B$6,MATCH(D39,Restaurants!$A$2:$A$6,0)),"") -> Trailhead Burger Co. #101 - San Antonio, TX | F39: 1000 | G39: =IFERROR(INDEX(Chart_of_Accounts!$B$2:$B$18,MATCH(F39,Chart_of_Accounts!$A$2:$A$18,0)),"") -> Cash | H39: =IFERROR(INDEX(Chart_of_Accounts!$C$2:$C$18,MATCH(F39,Chart_of_Accounts!$A$2:$A$18,0)),"") -> Asset | J39: 3300 | K39: Delivery platform commission fee | L39: Cash | M39: Delivery | N39: V05 | O39: =IFERROR(INDEX(Vendors!$B$2:$B$10,MATCH(N39,Vendors!$A$2:$A$10,0)),"") -> QuickDash Delivery Platform | P39: Restaurant Ops
A40: 20 | B40: T0020 | C40: 46030 | D40: 101 | E40: =IFERROR(INDEX(Restaurants!$B$2:$B$6,MATCH(D40,Restaurants!$A$2:$A$6,0)),"") -> Trailhead Burger Co. #101 - San Antonio, TX | F40: 1020 | G40: =IFERROR(INDEX(Chart_of_Accounts!$B$2:$B$18,MATCH(F40,Chart_of_Accounts!$A$2:$A$18,0)),"") -> Inventory | H40: =IFERROR(INDEX(Chart_of_Accounts!$C$2:$C$18,MATCH(F40,Chart_of_Accounts!$A$2:$A$18,0)),"") -> Asset | I40: 38430 | K40: Food & beverage inventory purchase | L40: N/A | M40: Corporate | N40: V01 | O40: =IFERROR(INDEX(Vendors!$B$2:$B$10,MATCH(N40,Vendors!$A$2:$A$10,0)),"") -> Gulf Coast Meat Supply | P40: Supply Chain
...

Sheet General_Ledger
A1: Account_ID | B1: Account_Name | C1: Account_Type | D1: Total_Debits | E1: Total_Credits | F1: Net_Balance | G1: Normal_Balance
A2: =Chart_of_Accounts!A2 -> 1000 | B2: =Chart_of_Accounts!B2 -> Cash | C2: =Chart_of_Accounts!C2 -> Asset | D2: =SUMIF(Transactions!$F$2:$F$411,A2,Transactions!$I$2:$I$411) -> 2254604 | E2: =SUMIF(Transactions!$F$2:$F$411,A2,Transactions!$J$2:$J$411) -> 1648615.7 | F2: =D2-E2 -> 605988.32 | G2: =Chart_of_Accounts!D2 -> Debit
A3: =Chart_of_Accounts!A3 -> 1010 | B3: =Chart_of_Accounts!B3 -> Accounts Receivable | C3: =Chart_of_Accounts!C3 -> Asset | D3: =SUMIF(Transactions!$F$2:$F$411,A3,Transactions!$I$2:$I$411) -> 316404 | E3: =SUMIF(Transactions!$F$2:$F$411,A3,Transactions!$J$2:$J$411) -> 316404 | F3: =D3-E3 -> 0 | G3: =Chart_of_Accounts!D3 -> Debit
A4: =Chart_of_Accounts!A4 -> 1020 | B4: =Chart_of_Accounts!B4 -> Inventory | C4: =Chart_of_Accounts!C4 -> Asset | D4: =SUMIF(Transactions!$F$2:$F$411,A4,Transactions!$I$2:$I$411) -> 566289.11 | E4: =SUMIF(Transactions!$F$2:$F$411,A4,Transactions!$J$2:$J$411) -> 539322.96 | F4: =D4-E4 -> 26966.15 | G4: =Chart_of_Accounts!D4 -> Debit
A5: =Chart_of_Accounts!A5 -> 1030 | B5: =Chart_of_Accounts!B5 -> Equipment | C5: =Chart_of_Accounts!C5 -> Asset | D5: =SUMIF(Transactions!$F$2:$F$411,A5,Transactions!$I$2:$I$411) -> 475000 | E5: =SUMIF(Transactions!$F$2:$F$411,A5,Transactions!$J$2:$J$411) -> 0 | F5: =D5-E5 -> 475000 | G5: =Chart_of_Accounts!D5 -> Debit
A6: =Chart_of_Accounts!A6 -> 2000 | B6: =Chart_of_Accounts!B6 -> Accounts Payable | C6: =Chart_of_Accounts!C6 -> Liability | D6: =SUMIF(Transactions!$F$2:$F$411,A6,Transactions!$I$2:$I$411) -> 330572.66 | E6: =SUMIF(Transactions!$F$2:$F$411,A6,Transactions!$J$2:$J$411) -> 566289.11 | F6: =D6-E6 -> -235716.45 | G6: =Chart_of_Accounts!D6 -> Credit
A7: =Chart_of_Accounts!A7 -> 2010 | B7: =Chart_of_Accounts!B7 -> Loan Payable | C7: =Chart_of_Accounts!C7 -> Liability | D7: =SUMIF(Transactions!$F$2:$F$411,A7,Transactions!$I$2:$I$411) -> 0 | E7: =SUMIF(Transactions!$F$2:$F$411,A7,Transactions!$J$2:$J$411) -> 200000 | F7: =D7-E7 -> -200000 | G7: =Chart_of_Accounts!D7 -> Credit
A8: =Chart_of_Accounts!A8 -> 3000 | B8: =Chart_of_Accounts!B8 -> Owner's Equity | C8: =Chart_of_Accounts!C8 -> Equity | D8: =SUMIF(Transactions!$F$2:$F$411,A8,Transactions!$I$2:$I$411) -> 0 | E8: =SUMIF(Transactions!$F$2:$F$411,A8,Transactions!$J$2:$J$411) -> 300000 | F8: =D8-E8 -> -300000 | G8: =Chart_of_Accounts!D8 -> Credit
A9: =Chart_of_Accounts!A9 -> 4000 | B9: =Chart_of_Accounts!B9 -> Restaurant Sales | C9: =Chart_of_Accounts!C9 -> Revenue | D9: =SUMIF(Transactions!$F$2:$F$411,A9,Transactions!$I$2:$I$411) -> 0 | E9: =SUMIF(Transactions!$F$2:$F$411,A9,Transactions!$J$2:$J$411) -> 1438200 | F9: =D9-E9 -> -1438200 | G9: =Chart_of_Accounts!D9 -> Credit
A10: =Chart_of_Accounts!A10 -> 4010 | B10: =Chart_of_Accounts!B10 -> Delivery Sales | C10: =Chart_of_Accounts!C10 -> Revenue | D10: =SUMIF(Transactions!$F$2:$F$411,A10,Transactions!$I$2:$I$411) -> 0 | E10: =SUMIF(Transactions!$F$2:$F$411,A10,Transactions!$J$2:$J$411) -> 316404 | F10: =D10-E10 -> -316404 | G10: =Chart_of_Accounts!D10 -> Credit
A11: =Chart_of_Accounts!A11 -> 5000 | B11: =Chart_of_Accounts!B11 -> Food Cost | C11: =Chart_of_Accounts!C11 -> Expense | D11: =SUMIF(Transactions!$F$2:$F$411,A11,Transactions!$I$2:$I$411) -> 539322.96 | E11: =SUMIF(Transactions!$F$2:$F$411,A11,Transactions!$J$2:$J$411) -> 0 | F11: =D11-E11 -> 539322.96 | G11: =Chart_of_Accounts!D11 -> Debit
A12: =Chart_of_Accounts!A12 -> 5010 | B12: =Chart_of_Accounts!B12 -> Labor | C12: =Chart_of_Accounts!C12 -> Expense | D12: =SUMIF(Transactions!$F$2:$F$411,A12,Transactions!$I$2:$I$411) -> 456197.04 | E12: =SUMIF(Transactions!$F$2:$F$411,A12,Transactions!$J$2:$J$411) -> 0 | F12: =D12-E12 -> 456197.04 | G12: =Chart_of_Accounts!D12 -> Debit
A13: =Chart_of_Accounts!A13 -> 5020 | B13: =Chart_of_Accounts!B13 -> Rent | C13: =Chart_of_Accounts!C13 -> Expense | D13: =SUMIF(Transactions!$F$2:$F$411,A13,Transactions!$I$2:$I$411) -> 135000 | E13: =SUMIF(Transactions!$F$2:$F$411,A13,Transactions!$J$2:$J$411) -> 0 | F13: =D13-E13 -> 135000 | G13: =Chart_of_Accounts!D13 -> Debit
... A18: =Chart_of_Accounts!A18 -> 5070 | B18: =Chart_of_Accounts!B18 -> Franchise Fees | C18: =Chart_of_Accounts!C18 -> Expense | D18: =SUMIF(Transactions!$F$2:$F$411,A18,Transactions!$I$2:$I$411) -> 70184.16 | E18: =SUMIF(Transactions!$F$2:$F$411,A18,Transactions!$J$2:$J$411) -> 0 | F18: =D18-E18 -> 70184.16 | G18: =Chart_of_Accounts!D18 -> Debit

Sheet Trial_Balance
A1: Trial Balance Check
A3: Total Debits (all accounts) | B3: =SUM(General_Ledger!D2:D18) -> 5325235.8
A4: Total Credits (all accounts) | B4: =SUM(General_Ledger!E2:E18) -> 5325235.8
A5: Difference (should be $0) | B5: =B3-B4 -> 0
A6: Status | B6: =IF(B5=0,"BALANCED","OUT OF BALANCE - investigate") -> BALANCED

Sheet Income_Statement
A1: Trailhead Burger Co. — Monthly Income Statement (All Restaurants)
A3: Line Item | B3: January 2026 | C3: February 2026 | D3: March 2026
A4: Restaurant Sales | B4: =SUMIFS(Transactions!$J$2:$J$411,Transactions!$F$2:$F$411,"4000",Transactions!$C$2:$C$411,">="&DATE(2026,1,1),Transactions!$C$2:$C$411,"<="&EOMONTH(DATE(2026,1,1),0))-SUMIFS(Transactions!$I$2:$I$411,Transactions!$F$2:$F$411,"4000",Transactions!$C$2:$C$411,">="&DATE(2026,1,1),Transactions!$C$2:$C$411,"<="&EOMONTH(DATE(2026,1,1),0)) -> 470000 | C4: =SUMIFS(Transactions!$J$2:$J$411,Transactions!$F$2:$F$411,"4000",Transactions!$C$2:$C$411,">="&DATE(2026,2,1),Transactions!$C$2:$C$411,"<="&EOMONTH(DATE(2026,2,1),0))-SUMIFS(Transactions!$I$2:$I$411,Transactions!$F$2:$F$411,"4000",Transactions!$C$2:$C$411,">="&DATE(2026,2,1),Transactions!$C$2:$C$411,"<="&EOMONTH(DATE(2026,2,1),0)) -> 479400 | D4: =SUMIFS(Transactions!$J$2:$J$411,Transactions!$F$2:$F$411,"4000",Transactions!$C$2:$C$411,">="&DATE(2026,3,1),Transactions!$C$2:$C$411,"<="&EOMONTH(DATE(2026,3,1),0))-SUMIFS(Transactions!$I$2:$I$411,Transactions!$F$2:$F$411,"4000",Transactions!$C$2:$C$411,">="&DATE(2026,3,1),Transactions!$C$2:$C$411,"<="&EOMONTH(DATE(2026,3,1),0)) -> 488800
A5: Delivery Sales | B5: =SUMIFS(Transactions!$J$2:$J$411,Transactions!$F$2:$F$411,"4010",Transactions!$C$2:$C$411,">="&DATE(2026,1,1),Transactions!$C$2:$C$411,"<="&EOMONTH(DATE(2026,1,1),0))-SUMIFS(Transactions!$I$2:$I$411,Transactions!$F$2:$F$411,"4010",Transactions!$C$2:$C$411,">="&DATE(2026,1,1),Transactions!$C$2:$C$411,"<="&EOMONTH(DATE(2026,1,1),0)) -> 103400 | C5: =SUMIFS(Transactions!$J$2:$J$411,Transactions!$F$2:$F$411,"4010",Transactions!$C$2:$C$411,">="&DATE(2026,2,1),Transactions!$C$2:$C$411,"<="&EOMONTH(DATE(2026,2,1),0))-SUMIFS(Transactions!$I$2:$I$411,Transactions!$F$2:$F$411,"4010",Transactions!$C$2:$C$411,">="&DATE(2026,2,1),Transactions!$C$2:$C$411,"<="&EOMONTH(DATE(2026,2,1),0)) -> 105468 | D5: =SUMIFS(Transactions!$J$2:$J$411,Transactions!$F$2:$F$411,"4010",Transactions!$C$2:$C$411,">="&DATE(2026,3,1),Transactions!$C$2:$C$411,"<="&EOMONTH(DATE(2026,3,1),0))-SUMIFS(Transactions!$I$2:$I$411,Transactions!$F$2:$F$411,"4010",Transactions!$C$2:$C$411,">="&DATE(2026,3,1),Transactions!$C$2:$C$411,"<="&EOMONTH(DATE(2026,3,1),0)) -> 107536
A6: TOTAL REVENUE | B6: =B4+B5 -> 573400 | C6: =C4+C5 -> 584868 | D6: =D4+D5 -> 596336
A7: Food Cost | B7: =SUMIFS(Transactions!$I$2:$I$411,Transactions!$F$2:$F$411,"5000",Transactions!$C$2:$C$411,">="&DATE(2026,1,1),Transactions!$C$2:$C$411,"<="&EOMONTH(DATE(2026,1,1),0))-SUMIFS(Transactions!$J$2:$J$411,Transactions!$F$2:$F$411,"5000",Transactions!$C$2:$C$411,">="&DATE(2026,1,1),Transactions!$C$2:$C$411,"<="&EOMONTH(DATE(2026,1,1),0)) -> 172020 | C7: =SUMIFS(Transactions!$I$2:$I$411,Transactions!$F$2:$F$411,"5000",Transactions!$C$2:$C$411,">="&DATE(2026,2,1),Transactions!$C$2:$C$411,"<="&EOMONTH(DATE(2026,2,1),0))-SUMIFS(Transactions!$J$2:$J$411,Transactions!$F$2:$F$411,"5000",Transactions!$C$2:$C$411,">="&DATE(2026,2,1),Transactions!$C$2:$C$411,"<="&EOMONTH(DATE(2026,2,1),0)) -> 175460.4 | D7: =SUMIFS(Transactions!$I$2:$I$411,Transactions!$F$2:$F$411,"5000",Transactions!$C$2:$C$411,">="&DATE(2026,3,1),Transactions!$C$2:$C$411,"<="&EOMONTH(DATE(2026,3,1),0))-SUMIFS(Transactions!$J$2:$J$411,Transactions!$F$2:$F$411,"5000",Transactions!$C$2:$C$411,">="&DATE(2026,3,1),Transactions!$C$2:$C$411,"<="&EOMONTH(DATE(2026,3,1),0)) -> 191842.56
A8: Labor | B8: =SUMIFS(Transactions!$I$2:$I$411,Transactions!$F$2:$F$411,"5010",Transactions!$C$2:$C$411,">="&DATE(2026,1,1),Transactions!$C$2:$C$411,"<="&EOMONTH(DATE(2026,1,1),0))-SUMIFS(Transactions!$J$2:$J$411,Transactions!$F$2:$F$411,"5010",Transactions!$C$2:$C$411,">="&DATE(2026,1,1),Transactions!$C$2:$C$411,"<="&EOMONTH(DATE(2026,1,1),0)) -> 149084 | C8: =SUMIFS(Transactions!$I$2:$I$411,Transactions!$F$2:$F$411,"5010",Transactions!$C$2:$C$411,">="&DATE(2026,2,1),Transactions!$C$2:$C$411,"<="&EOMONTH(DATE(2026,2,1),0))-SUMIFS(Transactions!$J$2:$J$411,Transactions!$F$2:$F$411,"5010",Transactions!$C$2:$C$411,">="&DATE(2026,2,1),Transactions!$C$2:$C$411,"<="&EOMONTH(DATE(2026,2,1),0)) -> 152065.68 | D8: =SUMIFS(Transactions!$I$2:$I$411,Transactions!$F$2:$F$411,"5010",Transactions!$C$2:$C$411,">="&DATE(2026,3,1),Transactions!$C$2:$C$411,"<="&EOMONTH(DATE(2026,3,1),0))-SUMIFS(Transactions!$J$2:$J$411,Transactions!$F$2:$F$411,"5010",Transactions!$C$2:$C$411,">="&DATE(2026,3,1),Transactions!$C$2:$C$411,"<="&EOMONTH(DATE(2026,3,1),0)) -> 155047.36
A9: GROSS PROFIT | B9: =B6-B7-B8 -> 252296 | C9: =C6-C7-C8 -> 257341.92 | D9: =D6-D7-D8 -> 249446.08
A10: Rent | B10: =SUMIFS(Transactions!$I$2:$I$411,Transactions!$F$2:$F$411,"5020",Transactions!$C$2:$C$411,">="&DATE(2026,1,1),Transactions!$C$2:$C$411,"<="&EOMONTH(DATE(2026,1,1),0))-SUMIFS(Transactions!$J$2:$J$411,Transactions!$F$2:$F$411,"5020",Transactions!$C$2:$C$411,">="&DATE(2026,1,1),Transactions!$C$2:$C$411,"<="&EOMONTH(DATE(2026,1,1),0)) -> 45000 | C10: =SUMIFS(Transactions!$I$2:$I$411,Transactions!$F$2:$F$411,"5020",Transactions!$C$2:$C$411,">="&DATE(2026,2,1),Transactions!$C$2:$C$411,"<="&EOMONTH(DATE(2026,2,1),0))-SUMIFS(Transactions!$J$2:$J$411,Transactions!$F$2:$F$411,"5020",Transactions!$C$2:$C$411,">="&DATE(2026,2,1),Transactions!$C$2:$C$411,"<="&EOMONTH(DATE(2026,2,1),0)) -> 45000 | D10: =SUMIFS(Transactions!$I$2:$I$411,Transactions!$F$2:$F$411,"5020",Transactions!$C$2:$C$411,">="&DATE(2026,3,1),Transactions!$C$2:$C$411,"<="&EOMONTH(DATE(2026,3,1),0))-SUMIFS(Transactions!$J$2:$J$411,Transactions!$F$2:$F$411,"5020",Transactions!$C$2:$C$411,">="&DATE(2026,3,1),Transactions!$C$2:$C$411,"<="&EOMONTH(DATE(2026,3,1),0)) -> 45000
A11: Utilities | B11: =SUMIFS(Transactions!$I$2:$I$411,Transactions!$F$2:$F$411,"5030",Transactions!$C$2:$C$411,">="&DATE(2026,1,1),Transactions!$C$2:$C$411,"<="&EOMONTH(DATE(2026,1,1),0))-SUMIFS(Transactions!$J$2:$J$411,Transactions!$F$2:$F$411,"5030",Transactions!$C$2:$C$411,">="&DATE(2026,1,1),Transactions!$C$2:$C$411,"<="&EOMONTH(DATE(2026,1,1),0)) -> 12200 | C11: =SUMIFS(Transactions!$I$2:$I$411,Transactions!$F$2:$F$411,"5030",Transactions!$C$2:$C$411,">="&DATE(2026,2,1),Transactions!$C$2:$C$411,"<="&EOMONTH(DATE(2026,2,1),0))-SUMIFS(Transactions!$J$2:$J$411,Transactions!$F$2:$F$411,"5030",Transactions!$C$2:$C$411,">="&DATE(2026,2,1),Transactions!$C$2:$C$411,"<="&EOMONTH(DATE(2026,2,1),0)) -> 12566 | D11: =SUMIFS(Transactions!$I$2:$I$411,Transactions!$F$2:$F$411,"5030",Transactions!$C$2:$C$411,">="&DATE(2026,3,1),Transactions!$C$2:$C$411,"<="&EOMONTH(DATE(2026,3,1),0))-SUMIFS(Transactions!$J$2:$J$411,Transactions!$F$2:$F$411,"5030",Transactions!$C$2:$C$411,">="&DATE(2026,3,1),Transactions!$C$2:$C$411,"<="&EOMONTH(DATE(2026,3,1),0)) -> 12932
A12: Delivery Fees | B12: =SUMIFS(Transactions!$I$2:$I$411,Transactions!$F$2:$F$411,"5040",Transactions!$C$2:$C$411,">="&DATE(2026,1,1),Transactions!$C$2:$C$411,"<="&EOMONTH(DATE(2026,1,1),0))-SUMIFS(Transactions!$J$2:$J$411,Transactions!$F$2:$F$411,"5040",Transactions!$C$2:$C$411,">="&DATE(2026,1,1),Transactions!$C$2:$C$411,"<="&EOMONTH(DATE(2026,1,1),0)) -> 15510 | C12: =SUMIFS(Transactions!$I$2:$I$411,Transactions!$F$2:$F$411,"5040",Transactions!$C$2:$C$411,">="&DATE(2026,2,1),Transactions!$C$2:$C$411,"<="&EOMONTH(DATE(2026,2,1),0))-SUMIFS(Transactions!$J$2:$J$411,Transactions!$F$2:$F$411,"5040",Transactions!$C$2:$C$411,">="&DATE(2026,2,1),Transactions!$C$2:$C$411,"<="&EOMONTH(DATE(2026,2,1),0)) -> 15820.2 | D12: =SUMIFS(Transactions!$I$2:$I$411,Transactions!$F$2:$F$411,"5040",Transactions!$C$2:$C$411,">="&DATE(2026,3,1),Transactions!$C$2:$C$411,"<="&EOMONTH(DATE(2026,3,1),0))-SUMIFS(Transactions!$J$2:$J$411,Transactions!$F$2:$F$411,"5040",Transactions!$C$2:$C$411,">="&DATE(2026,3,1),Transactions!$C$2:$C$411,"<="&EOMONTH(DATE(2026,3,1),0)) -> 16130.4
A13: CC Processing Fees | B13: =SUMIFS(Transactions!$I$2:$I$411,Transactions!$F$2:$F$411,"5050",Transactions!$C$2:$C$411,">="&DATE(2026,1,1),Transactions!$C$2:$C$411,"<="&EOMONTH(DATE(2026,1,1),0))-SUMIFS(Transactions!$J$2:$J$411,Transactions!$F$2:$F$411,"5050",Transactions!$C$2:$C$411,">="&DATE(2026,1,1),Transactions!$C$2:$C$411,"<="&EOMONTH(DATE(2026,1,1),0)) -> 14335 | C13: =SUMIFS(Transactions!$I$2:$I$411,Transactions!$F$2:$F$411,"5050",Transactions!$C$2:$C$411,">="&DATE(2026,2,1),Transactions!$C$2:$C$411,"<="&EOMONTH(DATE(2026,2,1),0))-SUMIFS(Transactions!$J$2:$J$411,Transactions!$F$2:$F$411,"5050",Transactions!$C$2:$C$411,">="&DATE(2026,2,1),Transactions!$C$2:$C$411,"<="&EOMONTH(DATE(2026,2,1),0)) -> 14621.7 | D13: =SUMIFS(Transactions!$I$2:$I$411,Transactions!$F$2:$F$411,"5050",Transactions!$C$2:$C$411,">="&DATE(2026,3,1),Transactions!$C$2:$C$411,"<="&EOMONTH(DATE(2026,3,1),0))-SUMIFS(Transactions!$J$2:$J$411,Transactions!$F$2:$F$411,"5050",Transactions!$C$2:$C$411,">="&DATE(2026,3,1),Transactions!$C$2:$C$411,"<="&EOMONTH(DATE(2026,3,1),0)) -> 14908.4
A14: Marketing | B14: =SUMIFS(Transactions!$I$2:$I$411,Transactions!$F$2:$F$411,"5060",Transactions!$C$2:$C$411,">="&DATE(2026,1,1),Transactions!$C$2:$C$411,"<="&EOMONTH(DATE(2026,1,1),0))-SUMIFS(Transactions!$J$2:$J$411,Transactions!$F$2:$F$411,"5060",Transactions!$C$2:$C$411,">="&DATE(2026,1,1),Transactions!$C$2:$C$411,"<="&EOMONTH(DATE(2026,1,1),0)) -> 17202 | C14: =SUMIFS(Transactions!$I$2:$I$411,Transactions!$F$2:$F$411,"5060",Transactions!$C$2:$C$411,">="&DATE(2026,2,1),Transactions!$C$2:$C$411,"<="&EOMONTH(DATE(2026,2,1),0))-SUMIFS(Transactions!$J$2:$J$411,Transactions!$F$2:$F$411,"5060",Transactions!$C$2:$C$411,">="&DATE(2026,2,1),Transactions!$C$2:$C$411,"<="&EOMONTH(DATE(2026,2,1),0)) -> 17546.04 | D14: =SUMIFS(Transactions!$I$2:$I$411,Transactions!$F$2:$F$411,"5060",Transactions!$C$2:$C$411,">="&DATE(2026,3,1),Transactions!$C$2:$C$411,"<="&EOMONTH(DATE(2026,3,1),0))-SUMIFS(Transactions!$J$2:$J$411,Transactions!$F$2:$F$411,"5060",Transactions!$C$2:$C$411,">="&DATE(2026,3,1),Transactions!$C$2:$C$411,"<="&EOMONTH(DATE(2026,3,1),0)) -> 17890.08
A15: Franchise Fees | B15: =SUMIFS(Transactions!$I$2:$I$411,Transactions!$F$2:$F$411,"5070",Transactions!$C$2:$C$411,">="&DATE(2026,1,1),Transactions!$C$2:$C$411,"<="&EOMONTH(DATE(2026,1,1),0))-SUMIFS(Transactions!$J$2:$J$411,Transactions!$F$2:$F$411,"5070",Transactions!$C$2:$C$411,">="&DATE(2026,1,1),Transactions!$C$2:$C$411,"<="&EOMONTH(DATE(2026,1,1),0)) -> 22936 | C15: =SUMIFS(Transactions!$I$2:$I$411,Transactions!$F$2:$F$411,"5070",Transactions!$C$2:$C$411,">="&DATE(2026,2,1),Transactions!$C$2:$C$411,"<="&EOMONTH(DATE(2026,2,1),0))-SUMIFS(Transactions!$J$2:$J$411,Transactions!$F$2:$F$411,"5070",Transactions!$C$2:$C$411,">="&DATE(2026,2,1),Transactions!$C$2:$C$411,"<="&EOMONTH(DATE(2026,2,1),0)) -> 23394.72 | D15: =SUMIFS(Transactions!$I$2:$I$411,Transactions!$F$2:$F$411,"5070",Transactions!$C$2:$C$411,">="&DATE(2026,3,1),Transactions!$C$2:$C$411,"<="&EOMONTH(DATE(2026,3,1),0))-SUMIFS(Transactions!$J$2:$J$411,Transactions!$F$2:$F$411,"5070",Transactions!$C$2:$C$411,">="&DATE(2026,3,1),Transactions!$C$2:$C$411,"<="&EOMONTH(DATE(2026,3,1),0)) -> 23853.44
A16: TOTAL OPERATING EXPENSES | B16: =B10+B11+B12+B13+B14+B15 -> 127183 | C16: =C10+C11+C12+C13+C14+C15 -> 128948.66 | D16: =D10+D11+D12+D13+D14+D15 -> 130714.32
A17: OPERATING INCOME | B17: =B9-B16 -> 125113 | C17: =C9-C16 -> 128393.26 | D17: =D9-D16 -> 118731.76
A18: Operating Margin % | B18: =IFERROR(B17/B6,0) -> 0.21819498 | C18: =IFERROR(C17/C6,0) -> 0.21952519 | D18: =IFERROR(D17/D6,0) -> 0.19910212

Sheet Budget
A1: Budget Assumptions (edit the blue cells)
A3: Line Item | B3: January 2026 | C3: February 2026 | D3: March 2026
A4: Restaurant Sales | B4: 470000 | C4: 480000 | D4: 490000
A5: Delivery Sales | B5: 103000 | C5: 106000 | D5: 108000
A6: TOTAL REVENUE | B6: =B4+B5 -> 573000 | C6: =C4+C5 -> 586000 | D6: =D4+D5 -> 598000
A7: Food Cost | B7: 172000 | C7: 176000 | D7: 179000
A8: Labor | B8: 149000 | C8: 152000 | D8: 155000
A9: GROSS PROFIT | B9: =B6-B7-B8 -> 252000 | C9: =C6-C7-C8 -> 258000 | D9: =D6-D7-D8 -> 264000
A10: Rent | B10: 45000 | C10: 45000 | D10: 45000
A11: Utilities | B11: 12000 | C11: 12000 | D11: 12200
A12: Delivery Fees | B12: 17000 | C12: 17500 | D12: 17800
A13: CC Processing Fees | B13: 14300 | C13: 14600 | D13: 14900
A14: Marketing | B14: 17200 | C14: 17600 | D14: 17900
A15: Franchise Fees | B15: 22900 | C15: 23400 | D15: 23900
A16: TOTAL OPERATING EXPENSES | B16: =B10+B11+B12+B13+B14+B15 -> 128400 | C16: =C10+C11+C12+C13+C14+C15 -> 130100 | D16: =D10+D11+D12+D13+D14+D15 -> 131700
A17: OPERATING INCOME | B17: =B9-B16 -> 123600 | C17: =C9-C16 -> 127900 | D17: =D9-D16 -> 132300

Sheet Variance_Analysis
A1: Actual vs. Budget Variance
A3: Line Item | B3: Month | C3: Actual | D3: Budget | E3: $ Variance | F3: % Variance | G3: Favorable / Unfavorable
A4: Restaurant Sales | B4: January 2026 | C4: =Income_Statement!B4 -> 470000 | D4: =Budget!B4 -> 470000 | E4: =C4-D4 -> 0 | F4: =IFERROR(E4/D4,0) -> 0 | G4: =IF(E4>0,"Favorable",IF(E4<0,"Unfavorable","On Budget")) -> On Budget
A5: Restaurant Sales | B5: February 2026 | C5: =Income_Statement!C4 -> 479400 | D5: =Budget!C4 -> 480000 | E5: =C5-D5 -> -600 | F5: =IFERROR(E5/D5,0) -> -0.00125 | G5: =IF(E5>0,"Favorable",IF(E5<0,"Unfavorable","On Budget")) -> Unfavorable
A6: Restaurant Sales | B6: March 2026 | C6: =Income_Statement!D4 -> 488800 | D6: =Budget!D4 -> 490000 | E6: =C6-D6 -> -1200 | F6: =IFERROR(E6/D6,0) -> -0.0024489796 | G6: =IF(E6>0,"Favorable",IF(E6<0,"Unfavorable","On Budget")) -> Unfavorable
A7: Delivery Sales | B7: January 2026 | C7: =Income_Statement!B5 -> 103400 | D7: =Budget!B5 -> 103000 | E7: =C7-D7 -> 400 | F7: =IFERROR(E7/D7,0) -> 0.0038834951 | G7: =IF(E7>0,"Favorable",IF(E7<0,"Unfavorable","On Budget")) -> Favorable
A8: Delivery Sales | B8: February 2026 | C8: =Income_Statement!C5 -> 105468 | D8: =Budget!C5 -> 106000 | E8: =C8-D8 -> -532 | F8: =IFERROR(E8/D8,0) -> -0.0050188679 | G8: =IF(E8>0,"Favorable",IF(E8<0,"Unfavorable","On Budget")) -> Unfavorable
A9: Delivery Sales | B9: March 2026 | C9: =Income_Statement!D5 -> 107536 | D9: =Budget!D5 -> 108000 | E9: =C9-D9 -> -464 | F9: =IFERROR(E9/D9,0) -> -0.0042962963 | G9: =IF(E9>0,"Favorable",IF(E9<0,"Unfavorable","On Budget")) -> Unfavorable
A10: TOTAL REVENUE | B10: January 2026 | C10: =Income_Statement!B6 -> 573400 | D10: =Budget!B6 -> 573000 | E10: =C10-D10 -> 400 | F10: =IFERROR(E10/D10,0) -> 0.00069808028 | G10: =IF(E10>0,"Favorable",IF(E10<0,"Unfavorable","On Budget")) -> Favorable
A11: TOTAL REVENUE | B11: February 2026 | C11: =Income_Statement!C6 -> 584868 | D11: =Budget!C6 -> 586000 | E11: =C11-D11 -> -1132 | F11: =IFERROR(E11/D11,0) -> -0.0019317406 | G11: =IF(E11>0,"Favorable",IF(E11<0,"Unfavorable","On Budget")) -> Unfavorable
A12: TOTAL REVENUE | B12: March 2026 | C12: =Income_Statement!D6 -> 596336 | D12: =Budget!D6 -> 598000 | E12: =C12-D12 -> -1664 | F12: =IFERROR(E12/D12,0) -> -0.0027826087 | G12: =IF(E12>0,"Favorable",IF(E12<0,"Unfavorable","On Budget")) -> Unfavorable
A13: Food Cost | B13: January 2026 | C13: =Income_Statement!B7 -> 172020 | D13: =Budget!B7 -> 172000 | E13: =C13-D13 -> 20 | F13: =IFERROR(E13/D13,0) -> 0.00011627907 | G13: =IF(E13>0,"Unfavorable",IF(E13<0,"Favorable","On Budget")) -> Unfavorable
A14: Food Cost | B14: February 2026 | C14: =Income_Statement!C7 -> 175460.4 | D14: =Budget!C7 -> 176000 | E14: =C14-D14 -> -539.6 | F14: =IFERROR(E14/D14,0) -> -0.0030659091 | G14: =IF(E14>0,"Unfavorable",IF(E14<0,"Favorable","On Budget")) -> Favorable
A15: Food Cost | B15: March 2026 | C15: =Income_Statement!D7 -> 191842.56 | D15: =Budget!D7 -> 179000 | E15: =C15-D15 -> 12842.56 | F15: =IFERROR(E15/D15,0) -> 0.071746145 | G15: =IF(E15>0,"Unfavorable",IF(E15<0,"Favorable","On Budget")) -> Unfavorable
A16: Labor | B16: January 2026 | C16: =Income_Statement!B8 -> 149084 | D16: =Budget!B8 -> 149000 | E16: =C16-D16 -> 84 | F16: =IFERROR(E16/D16,0) -> 0.00056375839 | G16: =IF(E16>0,"Unfavorable",IF(E16<0,"Favorable","On Budget")) -> Unfavorable
A17: Labor | B17: February 2026 | C17: =Income_Statement!C8 -> 152065.68 | D17: =Budget!C8 -> 152000 | E17: =C17-D17 -> 65.68 | F17: =IFERROR(E17/D17,0) -> 0.00043210526 | G17: =IF(E17>0,"Unfavorable",IF(E17<0,"Favorable","On Budget")) -> Unfavorable
A18: Labor | B18: March 2026 | C18: =Income_Statement!D8 -> 155047.36 | D18: =Budget!D8 -> 155000 | E18: =C18-D18 -> 47.36 | F18: =IFERROR(E18/D18,0) -> 0.00030554839 | G18: =IF(E18>0,"Unfavorable",IF(E18<0,"Favorable","On Budget")) -> Unfavorable
A19: Rent | B19: January 2026 | C19: =Income_Statement!B10 -> 45000 | D19: =Budget!B10 -> 45000 | E19: =C19-D19 -> 0 | F19: =IFERROR(E19/D19,0) -> 0 | G19: =IF(E19>0,"Unfavorable",IF(E19<0,"Favorable","On Budget")) -> On Budget
A20: Rent | B20: February 2026 | C20: =Income_Statement!C10 -> 45000 | D20: =Budget!C10 -> 45000 | E20: =C20-D20 -> 0 | F20: =IFERROR(E20/D20,0) -> 0 | G20: =IF(E20>0,"Unfavorable",IF(E20<0,"Favorable","On Budget")) -> On Budget
A21: Rent | B21: March 2026 | C21: =Income_Statement!D10 -> 45000 | D21: =Budget!D10 -> 45000 | E21: =C21-D21 -> 0 | F21: =IFERROR(E21/D21,0) -> 0 | G21: =IF(E21>0,"Unfavorable",IF(E21<0,"Favorable","On Budget")) -> On Budget
A22: Utilities | B22: January 2026 | C22: =Income_Statement!B11 -> 12200 | D22: =Budget!B11 -> 12000 | E22: =C22-D22 -> 200 | F22: =IFERROR(E22/D22,0) -> 0.016666667 | G22: =IF(E22>0,"Unfavorable",IF(E22<0,"Favorable","On Budget")) -> Unfavorable
A23: Utilities | B23: February 2026 | C23: =Income_Statement!C11 -> 12566 | D23: =Budget!C11 -> 12000 | E23: =C23-D23 -> 566 | F23: =IFERROR(E23/D23,0) -> 0.047166667 | G23: =IF(E23>0,"Unfavorable",IF(E23<0,"Favorable","On Budget")) -> Unfavorable
A24: Utilities | B24: March 2026 | C24: =Income_Statement!D11 -> 12932 | D24: =Budget!D11 -> 12200 | E24: =C24-D24 -> 732 | F24: =IFERROR(E24/D24,0) -> 0.06 | G24: =IF(E24>0,"Unfavorable",IF(E24<0,"Favorable","On Budget")) -> Unfavorable
A25: Delivery Fees | B25: January 2026 | C25: =Income_Statement!B12 -> 15510 | D25: =Budget!B12 -> 17000 | E25: =C25-D25 -> -1490 | F25: =IFERROR(E25/D25,0) -> -0.087647059 | G25: =IF(E25>0,"Unfavorable",IF(E25<0,"Favorable","On Budget")) -> Favorable
A26: Delivery Fees | B26: February 2026 | C26: =Income_Statement!C12 -> 15820.2 | D26: =Budget!C12 -> 17500 | E26: =C26-D26 -> -1679.8 | F26: =IFERROR(E26/D26,0) -> -0.095988571 | G26: =IF(E26>0,"Unfavorable",IF(E26<0,"Favorable","On Budget")) -> Favorable
A27: Delivery Fees | B27: March 2026 | C27: =Income_Statement!D12 -> 16130.4 | D27: =Budget!D12 -> 17800 | E27: =C27-D27 -> -1669.6 | F27: =IFERROR(E27/D27,0) -> -0.093797753 | G27: =IF(E27>0,"Unfavorable",IF(E27<0,"Favorable","On Budget")) -> Favorable
A28: CC Processing Fees | B28: January 2026 | C28: =Income_Statement!B13 -> 14335 | D28: =Budget!B13 -> 14300 | E28: =C28-D28 -> 35 | F28: =IFERROR(E28/D28,0) -> 0.0024475524 | G28: =IF(E28>0,"Unfavorable",IF(E28<0,"Favorable","On Budget")) -> Unfavorable
A29: CC Processing Fees | B29: February 2026 | C29: =Income_Statement!C13 -> 14621.7 | D29: =Budget!C13 -> 14600 | E29: =C29-D29 -> 21.7 | F29: =IFERROR(E29/D29,0) -> 0.0014863014 | G29: =IF(E29>0,"Unfavorable",IF(E29<0,"Favorable","On Budget")) -> Unfavorable
A30: CC Processing Fees | B30: March 2026 | C30: =Income_Statement!D13 -> 14908.4 | D30: =Budget!D13 -> 14900 | E30: =C30-D30 -> 8.4 | F30: =IFERROR(E30/D30,0) -> 0.00056375839 | G30: =IF(E30>0,"Unfavorable",IF(E30<0,"Favorable","On Budget")) -> Unfavorable
A31: Marketing | B31: January 2026 | C31: =Income_Statement!B14 -> 17202 | D31: =Budget!B14 -> 17200 | E31: =C31-D31 -> 2 | F31: =IFERROR(E31/D31,0) -> 0.00011627907 | G31: =IF(E31>0,"Unfavorable",IF(E31<0,"Favorable","On Budget")) -> Unfavorable
A32: Marketing | B32: February 2026 | C32: =Income_Statement!C14 -> 17546.04 | D32: =Budget!C14 -> 17600 | E32: =C32-D32 -> -53.96 | F32: =IFERROR(E32/D32,0) -> -0.0030659091 | G32: =IF(E32>0,"Unfavorable",IF(E32<0,"Favorable","On Budget")) -> Favorable
A33: Marketing | B33: March 2026 | C33: =Income_Statement!D14 -> 17890.08 | D33: =Budget!D14 -> 17900 | E33: =C33-D33 -> -9.92 | F33: =IFERROR(E33/D33,0) -> -0.00055418994 | G33: =IF(E33>0,"Unfavorable",IF(E33<0,"Favorable","On Budget")) -> Favorable
A34: Franchise Fees | B34: January 2026 | C34: =Income_Statement!B15 -> 22936 | D34: =Budget!B15 -> 22900 | E34: =C34-D34 -> 36 | F34: =IFERROR(E34/D34,0) -> 0.0015720524 | G34: =IF(E34>0,"Unfavorable",IF(E34<0,"Favorable","On Budget")) -> Unfavorable
A35: Franchise Fees | B35: February 2026 | C35: =Income_Statement!C15 -> 23394.72 | D35: =Budget!C15 -> 23400 | E35: =C35-D35 -> -5.28 | F35: =IFERROR(E35/D35,0) -> -0.00022564103 | G35: =IF(E35>0,"Unfavorable",IF(E35<0,"Favorable","On Budget")) -> Favorable
A36: Franchise Fees | B36: March 2026 | C36: =Income_Statement!D15 -> 23853.44 | D36: =Budget!D15 -> 23900 | E36: =C36-D36 -> -46.56 | F36: =IFERROR(E36/D36,0) -> -0.0019481172 | G36: =IF(E36>0,"Unfavorable",IF(E36<0,"Favorable","On Budget")) -> Favorable
A37: OPERATING INCOME | B37: January 2026 | C37: =Income_Statement!B17 -> 125113 | D37: =Budget!B17 -> 123600 | E37: =C37-D37 -> 1513 | F37: =IFERROR(E37/D37,0) -> 0.0122411 | G37: =IF(E37>0,"Favorable",IF(E37<0,"Unfavorable","On Budget")) -> Favorable
A38: OPERATING INCOME | B38: February 2026 | C38: =Income_Statement!C17 -> 128393.26 | D38: =Budget!C17 -> 127900 | E38: =C38-D38 -> 493.26 | F38: =IFERROR(E38/D38,0) -> 0.0038566067 | G38: =IF(E38>0,"Favorable",IF(E38<0,"Unfavorable","On Budget")) -> Favorable
A39: OPERATING INCOME | B39: March 2026 | C39: =Income_Statement!D17 -> 118731.76 | D39: =Budget!D17 -> 132300 | E39: =C39-D39 -> -13568.24 | F39: =IFERROR(E39/D39,0) -> -0.10255661 | G39: =IF(E39>0,"Favorable",IF(E39<0,"Unfavorable","On Budget")) -> Unfavorable

Sheet Restaurant_Drilldown
A1: March 2026 Food Cost Variance by Restaurant
A2: Something looks off in the fleet-wide food cost variance for March. Use this breakdown to find which restaurant is driving it.
A4: Restaurant_ID | B4: Restaurant_Name | C4: March Revenue | D4: March Food Cost | E4: Food Cost % of Revenue
A5: 101 | B5: =IFERROR(INDEX(Restaurants!$B$2:$B$6,MATCH(A5,Restaurants!$A$2:$A$6,0)),"") -> Trailhead Burger Co. #101 - San Antonio, TX | C5: =SUMIFS(Transactions!$J$2:$J$411,Transactions!$D$2:$D$411,A5,Transactions!$F$2:$F$411,"4000",Transactions!$C$2:$C$411,">="&DATE(2026,3,1),Transactions!$C$2:$C$411,"<="&EOMONTH(DATE(2026,3,1),0))+SUMIFS(Transactions!$J$2:$J$411,Transactions!$D$2:$D$411,A5,Transactions!$F$2:$F$411,"4010",Transactions!$C$2:$C$411,">="&DATE(2026,3,1),Transactions!$C$2:$C$411,"<="&EOMONTH(DATE(2026,3,1),0)) -> 126880 | D5: =SUMIFS(Transactions!$I$2:$I$411,Transactions!$D$2:$D$411,A5,Transactions!$F$2:$F$411,"5000",Transactions!$C$2:$C$411,">="&DATE(2026,3,1),Transactions!$C$2:$C$411,"<="&EOMONTH(DATE(2026,3,1),0)) -> 38064 | E5: =IFERROR(D5/C5,0) -> 0.3
A6: 102 | B6: =IFERROR(INDEX(Restaurants!$B$2:$B$6,MATCH(A6,Restaurants!$A$2:$A$6,0)),"") -> Trailhead Burger Co. #102 - Austin, TX | C6: =SUMIFS(Transactions!$J$2:$J$411,Transactions!$D$2:$D$411,A6,Transactions!$F$2:$F$411,"4000",Transactions!$C$2:$C$411,">="&DATE(2026,3,1),Transactions!$C$2:$C$411,"<="&EOMONTH(DATE(2026,3,1),0))+SUMIFS(Transactions!$J$2:$J$411,Transactions!$D$2:$D$411,A6,Transactions!$F$2:$F$411,"4010",Transactions!$C$2:$C$411,">="&DATE(2026,3,1),Transactions!$C$2:$C$411,"<="&EOMONTH(DATE(2026,3,1),0)) -> 120536 | D6: =SUMIFS(Transactions!$I$2:$I$411,Transactions!$D$2:$D$411,A6,Transactions!$F$2:$F$411,"5000",Transactions!$C$2:$C$411,">="&DATE(2026,3,1),Transactions!$C$2:$C$411,"<="&EOMONTH(DATE(2026,3,1),0)) -> 36160.8 | E6: =IFERROR(D6/C6,0) -> 0.3
A7: 103 | B7: =IFERROR(INDEX(Restaurants!$B$2:$B$6,MATCH(A7,Restaurants!$A$2:$A$6,0)),"") -> Trailhead Burger Co. #103 - Corpus Christi, TX | C7: =SUMIFS(Transactions!$J$2:$J$411,Transactions!$D$2:$D$411,A7,Transactions!$F$2:$F$411,"4000",Transactions!$C$2:$C$411,">="&DATE(2026,3,1),Transactions!$C$2:$C$411,"<="&EOMONTH(DATE(2026,3,1),0))+SUMIFS(Transactions!$J$2:$J$411,Transactions!$D$2:$D$411,A7,Transactions!$F$2:$F$411,"4010",Transactions!$C$2:$C$411,">="&DATE(2026,3,1),Transactions!$C$2:$C$411,"<="&EOMONTH(DATE(2026,3,1),0)) -> 101504 | D7: =SUMIFS(Transactions!$I$2:$I$411,Transactions!$D$2:$D$411,A7,Transactions!$F$2:$F$411,"5000",Transactions!$C$2:$C$411,">="&DATE(2026,3,1),Transactions!$C$2:$C$411,"<="&EOMONTH(DATE(2026,3,1),0)) -> 30451.2 | E7: =IFERROR(D7/C7,0) -> 0.3
A8: 104 | B8: =IFERROR(INDEX(Restaurants!$B$2:$B$6,MATCH(A8,Restaurants!$A$2:$A$6,0)),"") -> Trailhead Burger Co. #104 - Laredo, TX | C8: =SUMIFS(Transactions!$J$2:$J$411,Transactions!$D$2:$D$411,A8,Transactions!$F$2:$F$411,"4000",Transactions!$C$2:$C$411,">="&DATE(2026,3,1),Transactions!$C$2:$C$411,"<="&EOMONTH(DATE(2026,3,1),0))+SUMIFS(Transactions!$J$2:$J$411,Transactions!$D$2:$D$411,A8,Transactions!$F$2:$F$411,"4010",Transactions!$C$2:$C$411,">="&DATE(2026,3,1),Transactions!$C$2:$C$411,"<="&EOMONTH(DATE(2026,3,1),0)) -> 107848 | D8: =SUMIFS(Transactions!$I$2:$I$411,Transactions!$D$2:$D$411,A8,Transactions!$F$2:$F$411,"5000",Transactions!$C$2:$C$411,">="&DATE(2026,3,1),Transactions!$C$2:$C$411,"<="&EOMONTH(DATE(2026,3,1),0)) -> 45296.16 | E8: =IFERROR(D8/C8,0) -> 0.42
A9: 105 | B9: =IFERROR(INDEX(Restaurants!$B$2:$B$6,MATCH(A9,Restaurants!$A$2:$A$6,0)),"") -> Trailhead Burger Co. #105 - Houston, TX | C9: =SUMIFS(Transactions!$J$2:$J$411,Transactions!$D$2:$D$411,A9,Transactions!$F$2:$F$411,"4000",Transactions!$C$2:$C$411,">="&DATE(2026,3,1),Transactions!$C$2:$C$411,"<="&EOMONTH(DATE(2026,3,1),0))+SUMIFS(Transactions!$J$2:$J$411,Transactions!$D$2:$D$411,A9,Transactions!$F$2:$F$411,"4010",Transactions!$C$2:$C$411,">="&DATE(2026,3,1),Transactions!$C$2:$C$411,"<="&EOMONTH(DATE(2026,3,1),0)) -> 139568 | D9: =SUMIFS(Transactions!$I$2:$I$411,Transactions!$D$2:$D$411,A9,Transactions!$F$2:$F$411,"5000",Transactions!$C$2:$C$411,">="&DATE(2026,3,1),Transactions!$C$2:$C$411,"<="&EOMONTH(DATE(2026,3,1),0)) -> 41870.4 | E9: =IFERROR(D9/C9,0) -> 0.3
B11: Fleet Average Food Cost % | E11: =AVERAGE(E5:E9) -> 0.324
